I'm sorry, but an uncaught exception occurred.

While running game code:
  File "game/script.rpy", line 82, in script
    сork "Так, подожди, подожди. Ну, ладно, питание отрубили, так должен же быть тут какой-то генератор, чтоб не портилось ничего."
Exception: Sayer 'сork' is not defined.

-- Full Traceback ------------------------------------------------------------

Full traceback:
  File "game/script.rpy", line 82, in script
    сork "Так, подожди, подожди. Ну, ладно, питание отрубили, так должен же быть тут какой-то генератор, чтоб не портилось ничего."
  File "C:\Users\mpn19\Desktop\renpy\renpy-8.0.3-sdk\renpy\ast.py", line 881, in execute
    who = eval_who(self.who, self.who_fast)
  File "C:\Users\mpn19\Desktop\renpy\renpy-8.0.3-sdk\renpy\ast.py", line 774, in eval_who
    raise Exception("Sayer '%s' is not defined." % who)
Exception: Sayer 'сork' is not defined.

Windows-10-10.0.19043 AMD64
Ren'Py 8.0.3.22090809
Corkscrew novel 1.0
Tue Nov  1 10:57:57 2022
